[2023-11-30T10:49:00.210+0000] {taskinstance.py:1159} INFO - Dependencies all met for dep_context=non-requeueable deps ti=<TaskInstance: download_s3.download_csv manual__2023-11-30T10:48:37.595542+00:00 [queued]>
[2023-11-30T10:49:00.307+0000] {taskinstance.py:1159} INFO - Dependencies all met for dep_context=requeueable deps ti=<TaskInstance: download_s3.download_csv manual__2023-11-30T10:48:37.595542+00:00 [queued]>
[2023-11-30T10:49:00.307+0000] {taskinstance.py:1361} INFO - Starting attempt 1 of 1
[2023-11-30T10:49:00.899+0000] {taskinstance.py:1382} INFO - Executing <Task(PythonOperator): download_csv> on 2023-11-30 10:48:37.595542+00:00
[2023-11-30T10:49:01.101+0000] {standard_task_runner.py:57} INFO - Started process 1280 to run task
[2023-11-30T10:49:02.352+0000] {standard_task_runner.py:84} INFO - Running: ['***', 'tasks', 'run', 'download_s3', 'download_csv', 'manual__2023-11-30T10:48:37.595542+00:00', '--job-id', '102', '--raw', '--subdir', 'DAGS_FOLDER/download_s3.py', '--cfg-path', '/tmp/tmpk2mgz4vs']
[2023-11-30T10:49:02.359+0000] {standard_task_runner.py:85} INFO - Job 102: Subtask download_csv
[2023-11-30T10:49:14.222+0000] {task_command.py:416} INFO - Running <TaskInstance: download_s3.download_csv manual__2023-11-30T10:48:37.595542+00:00 [running]> on host ef0d87b1d156
[2023-11-30T10:49:19.761+0000] {taskinstance.py:1662} INFO - Exporting env vars: AIRFLOW_CTX_DAG_OWNER='Dashrath' AIRFLOW_CTX_DAG_ID='download_s3' AIRFLOW_CTX_TASK_ID='download_csv' AIRFLOW_CTX_EXECUTION_DATE='2023-11-30T10:48:37.595542+00:00' AIRFLOW_CTX_TRY_NUMBER='1' AIRFLOW_CTX_DAG_RUN_ID='manual__2023-11-30T10:48:37.595542+00:00'
[2023-11-30T10:49:19.800+0000] {taskinstance.py:1937} ERROR - Task failed with exception
Traceback (most recent call last):
  File "/home/airflow/.local/lib/python3.8/site-packages/airflow/operators/python.py", line 192, in execute
    return_value = self.execute_callable()
  File "/home/airflow/.local/lib/python3.8/site-packages/airflow/operators/python.py", line 209, in execute_callable
    return self.python_callable(*self.op_args, **self.op_kwargs)
  File "/opt/airflow/dags/download_s3.py", line 21, in download
    hook.download_file(bucket_name=bucket_name, key=key, filename =filename )
  File "/home/airflow/.local/lib/python3.8/site-packages/airflow/providers/amazon/aws/hooks/s3.py", line 120, in wrapper
    bound_args = function_signature.bind(*args, **kwargs)
  File "/usr/local/lib/python3.8/inspect.py", line 3037, in bind
    return self._bind(args, kwargs)
  File "/usr/local/lib/python3.8/inspect.py", line 3026, in _bind
    raise TypeError(
TypeError: got an unexpected keyword argument 'filename'
[2023-11-30T10:49:20.341+0000] {taskinstance.py:1400} INFO - Marking task as FAILED. dag_id=download_s3, task_id=download_csv, execution_date=20231130T104837, start_date=20231130T104900, end_date=20231130T104920
[2023-11-30T10:49:23.549+0000] {standard_task_runner.py:104} ERROR - Failed to execute job 102 for task download_csv (got an unexpected keyword argument 'filename'; 1280)
[2023-11-30T10:49:23.888+0000] {local_task_job_runner.py:228} INFO - Task exited with return code 1
[2023-11-30T10:49:25.581+0000] {taskinstance.py:2778} INFO - 0 downstream tasks scheduled from follow-on schedule check
