[2023-11-30T13:23:43.580+0000] {taskinstance.py:1159} INFO - Dependencies all met for dep_context=non-requeueable deps ti=<TaskInstance: aa.download_s3_file_task manual__2023-11-30T13:22:00.815408+00:00 [queued]>
[2023-11-30T13:23:43.713+0000] {taskinstance.py:1159} INFO - Dependencies all met for dep_context=requeueable deps ti=<TaskInstance: aa.download_s3_file_task manual__2023-11-30T13:22:00.815408+00:00 [queued]>
[2023-11-30T13:23:43.713+0000] {taskinstance.py:1361} INFO - Starting attempt 1 of 1
[2023-11-30T13:23:43.919+0000] {taskinstance.py:1382} INFO - Executing <Task(PythonOperator): download_s3_file_task> on 2023-11-30 13:22:00.815408+00:00
[2023-11-30T13:23:44.000+0000] {standard_task_runner.py:57} INFO - Started process 2694 to run task
[2023-11-30T13:23:44.001+0000] {standard_task_runner.py:84} INFO - Running: ['***', 'tasks', 'run', 'aa', 'download_s3_file_task', 'manual__2023-11-30T13:22:00.815408+00:00', '--job-id', '112', '--raw', '--subdir', 'DAGS_FOLDER/aa.py', '--cfg-path', '/tmp/tmp4dnoezho']
[2023-11-30T13:23:44.052+0000] {standard_task_runner.py:85} INFO - Job 112: Subtask download_s3_file_task
[2023-11-30T13:23:45.173+0000] {task_command.py:416} INFO - Running <TaskInstance: aa.download_s3_file_task manual__2023-11-30T13:22:00.815408+00:00 [running]> on host ef0d87b1d156
[2023-11-30T13:23:53.301+0000] {taskinstance.py:1662} INFO - Exporting env vars: AIRFLOW_CTX_DAG_OWNER='Dashrath' AIRFLOW_CTX_DAG_ID='aa' AIRFLOW_CTX_TASK_ID='download_s3_file_task' AIRFLOW_CTX_EXECUTION_DATE='2023-11-30T13:22:00.815408+00:00' AIRFLOW_CTX_TRY_NUMBER='1' AIRFLOW_CTX_DAG_RUN_ID='manual__2023-11-30T13:22:00.815408+00:00'
[2023-11-30T13:23:53.366+0000] {taskinstance.py:1937} ERROR - Task failed with exception
Traceback (most recent call last):
  File "/home/airflow/.local/lib/python3.8/site-packages/airflow/operators/python.py", line 192, in execute
    return_value = self.execute_callable()
  File "/home/airflow/.local/lib/python3.8/site-packages/airflow/operators/python.py", line 209, in execute_callable
    return self.python_callable(*self.op_args, **self.op_kwargs)
  File "/opt/airflow/dags/aa.py", line 22, in download_s3_file
    s3_hook.download_file(bucket_name=bucket_name, key=key,filename=filename)
  File "/home/airflow/.local/lib/python3.8/site-packages/airflow/providers/amazon/aws/hooks/s3.py", line 120, in wrapper
    bound_args = function_signature.bind(*args, **kwargs)
  File "/usr/local/lib/python3.8/inspect.py", line 3037, in bind
    return self._bind(args, kwargs)
  File "/usr/local/lib/python3.8/inspect.py", line 3026, in _bind
    raise TypeError(
TypeError: got an unexpected keyword argument 'filename'
[2023-11-30T13:23:54.001+0000] {taskinstance.py:1400} INFO - Marking task as FAILED. dag_id=aa, task_id=download_s3_file_task, execution_date=20231130T132200, start_date=20231130T132343, end_date=20231130T132353
[2023-11-30T13:23:54.558+0000] {standard_task_runner.py:104} ERROR - Failed to execute job 112 for task download_s3_file_task (got an unexpected keyword argument 'filename'; 2694)
[2023-11-30T13:23:54.726+0000] {local_task_job_runner.py:228} INFO - Task exited with return code 1
[2023-11-30T13:23:55.416+0000] {taskinstance.py:2778} INFO - 0 downstream tasks scheduled from follow-on schedule check
