[2023-11-30T13:19:10.776+0000] {taskinstance.py:1159} INFO - Dependencies all met for dep_context=non-requeueable deps ti=<TaskInstance: aa.download_s3_file_task manual__2023-11-30T13:18:22.188604+00:00 [queued]>
[2023-11-30T13:19:10.904+0000] {taskinstance.py:1159} INFO - Dependencies all met for dep_context=requeueable deps ti=<TaskInstance: aa.download_s3_file_task manual__2023-11-30T13:18:22.188604+00:00 [queued]>
[2023-11-30T13:19:10.904+0000] {taskinstance.py:1361} INFO - Starting attempt 1 of 1
[2023-11-30T13:19:11.161+0000] {taskinstance.py:1382} INFO - Executing <Task(PythonOperator): download_s3_file_task> on 2023-11-30 13:18:22.188604+00:00
[2023-11-30T13:19:11.210+0000] {standard_task_runner.py:84} INFO - Running: ['***', 'tasks', 'run', 'aa', 'download_s3_file_task', 'manual__2023-11-30T13:18:22.188604+00:00', '--job-id', '111', '--raw', '--subdir', 'DAGS_FOLDER/aa.py', '--cfg-path', '/tmp/tmpd5iny4i9']
[2023-11-30T13:19:11.211+0000] {standard_task_runner.py:57} INFO - Started process 2640 to run task
[2023-11-30T13:19:11.233+0000] {standard_task_runner.py:85} INFO - Job 111: Subtask download_s3_file_task
[2023-11-30T13:19:12.770+0000] {task_command.py:416} INFO - Running <TaskInstance: aa.download_s3_file_task manual__2023-11-30T13:18:22.188604+00:00 [running]> on host ef0d87b1d156
[2023-11-30T13:19:14.086+0000] {taskinstance.py:1662} INFO - Exporting env vars: AIRFLOW_CTX_DAG_OWNER='Dashrath' AIRFLOW_CTX_DAG_ID='aa' AIRFLOW_CTX_TASK_ID='download_s3_file_task' AIRFLOW_CTX_EXECUTION_DATE='2023-11-30T13:18:22.188604+00:00' AIRFLOW_CTX_TRY_NUMBER='1' AIRFLOW_CTX_DAG_RUN_ID='manual__2023-11-30T13:18:22.188604+00:00'
[2023-11-30T13:19:14.102+0000] {taskinstance.py:1937} ERROR - Task failed with exception
Traceback (most recent call last):
  File "/home/airflow/.local/lib/python3.8/site-packages/airflow/operators/python.py", line 192, in execute
    return_value = self.execute_callable()
  File "/home/airflow/.local/lib/python3.8/site-packages/airflow/operators/python.py", line 209, in execute_callable
    return self.python_callable(*self.op_args, **self.op_kwargs)
  File "/opt/airflow/dags/aa.py", line 22, in download_s3_file
    s3_hook.download_file(bucket_name=bucket_name, key=key,filename=filename)
  File "/home/airflow/.local/lib/python3.8/site-packages/airflow/providers/amazon/aws/hooks/s3.py", line 120, in wrapper
    bound_args = function_signature.bind(*args, **kwargs)
  File "/usr/local/lib/python3.8/inspect.py", line 3037, in bind
    return self._bind(args, kwargs)
  File "/usr/local/lib/python3.8/inspect.py", line 3026, in _bind
    raise TypeError(
TypeError: got an unexpected keyword argument 'filename'
[2023-11-30T13:19:14.267+0000] {taskinstance.py:1400} INFO - Marking task as FAILED. dag_id=aa, task_id=download_s3_file_task, execution_date=20231130T131822, start_date=20231130T131910, end_date=20231130T131914
[2023-11-30T13:19:14.611+0000] {standard_task_runner.py:104} ERROR - Failed to execute job 111 for task download_s3_file_task (got an unexpected keyword argument 'filename'; 2640)
[2023-11-30T13:19:14.685+0000] {local_task_job_runner.py:228} INFO - Task exited with return code 1
[2023-11-30T13:19:15.054+0000] {taskinstance.py:2778} INFO - 0 downstream tasks scheduled from follow-on schedule check
