[2023-11-29T16:41:01.540+0000] {taskinstance.py:1159} INFO - Dependencies all met for dep_context=non-requeueable deps ti=<TaskInstance: s3_upload_dag_20.upload_to_s3 manual__2023-11-29T16:37:23.025954+00:00 [queued]>
[2023-11-29T16:41:01.661+0000] {taskinstance.py:1159} INFO - Dependencies all met for dep_context=requeueable deps ti=<TaskInstance: s3_upload_dag_20.upload_to_s3 manual__2023-11-29T16:37:23.025954+00:00 [queued]>
[2023-11-29T16:41:01.661+0000] {taskinstance.py:1361} INFO - Starting attempt 1 of 2
[2023-11-29T16:41:01.946+0000] {taskinstance.py:1382} INFO - Executing <Task(PythonOperator): upload_to_s3> on 2023-11-29 16:37:23.025954+00:00
[2023-11-29T16:41:01.954+0000] {standard_task_runner.py:57} INFO - Started process 3139 to run task
[2023-11-29T16:41:01.989+0000] {standard_task_runner.py:84} INFO - Running: ['***', 'tasks', 'run', 's3_upload_dag_20', 'upload_to_s3', 'manual__2023-11-29T16:37:23.025954+00:00', '--job-id', '79', '--raw', '--subdir', 'DAGS_FOLDER/hook.py', '--cfg-path', '/tmp/tmpwfr28ikx']
[2023-11-29T16:41:02.007+0000] {standard_task_runner.py:85} INFO - Job 79: Subtask upload_to_s3
[2023-11-29T16:41:03.429+0000] {task_command.py:416} INFO - Running <TaskInstance: s3_upload_dag_20.upload_to_s3 manual__2023-11-29T16:37:23.025954+00:00 [running]> on host a89a99bc45b2
[2023-11-29T16:41:05.664+0000] {taskinstance.py:1662} INFO - Exporting env vars: AIRFLOW_CTX_DAG_OWNER='Raja' AIRFLOW_CTX_DAG_ID='s3_upload_dag_20' AIRFLOW_CTX_TASK_ID='upload_to_s3' AIRFLOW_CTX_EXECUTION_DATE='2023-11-29T16:37:23.025954+00:00' AIRFLOW_CTX_TRY_NUMBER='1' AIRFLOW_CTX_DAG_RUN_ID='manual__2023-11-29T16:37:23.025954+00:00'
[2023-11-29T16:41:05.920+0000] {base.py:73} INFO - Using connection ID 'aws_conn' for task execution.
[2023-11-29T16:41:05.921+0000] {connection_wrapper.py:378} INFO - AWS Connection (conn_id='aws_conn', conn_type='aws') credentials retrieved from login and password.
[2023-11-29T16:41:09.279+0000] {taskinstance.py:1937} ERROR - Task failed with exception
Traceback (most recent call last):
  File "/home/airflow/.local/lib/python3.8/site-packages/airflow/operators/python.py", line 192, in execute
    return_value = self.execute_callable()
  File "/home/airflow/.local/lib/python3.8/site-packages/airflow/operators/python.py", line 209, in execute_callable
    return self.python_callable(*self.op_args, **self.op_kwargs)
  File "/opt/airflow/dags/hook.py", line 20, in upload_to_s3
    hook.load_file(filename=filename, key=key, bucket_name=bucket_name)
  File "/home/airflow/.local/lib/python3.8/site-packages/airflow/providers/amazon/aws/hooks/s3.py", line 135, in wrapper
    return func(*bound_args.args, **bound_args.kwargs)
  File "/home/airflow/.local/lib/python3.8/site-packages/airflow/providers/amazon/aws/hooks/s3.py", line 89, in wrapper
    return func(*bound_args.args, **bound_args.kwargs)
  File "/home/airflow/.local/lib/python3.8/site-packages/airflow/providers/amazon/aws/hooks/s3.py", line 1067, in load_file
    raise ValueError(f"The key {key} already exists.")
ValueError: The key post_data.txt already exists.
[2023-11-29T16:41:09.415+0000] {taskinstance.py:1400} INFO - Marking task as UP_FOR_RETRY. dag_id=s3_upload_dag_20, task_id=upload_to_s3, execution_date=20231129T163723, start_date=20231129T164101, end_date=20231129T164109
[2023-11-29T16:41:09.545+0000] {standard_task_runner.py:104} ERROR - Failed to execute job 79 for task upload_to_s3 (The key post_data.txt already exists.; 3139)
[2023-11-29T16:41:09.651+0000] {local_task_job_runner.py:228} INFO - Task exited with return code 1
[2023-11-29T16:41:09.793+0000] {taskinstance.py:2778} INFO - 0 downstream tasks scheduled from follow-on schedule check
