[2023-11-29T16:11:36.186+0000] {taskinstance.py:1159} INFO - Dependencies all met for dep_context=non-requeueable deps ti=<TaskInstance: s3_pose_v2.upload_to_s3 scheduled__2023-11-28T14:33:17.814459+00:00 [queued]>
[2023-11-29T16:11:36.324+0000] {taskinstance.py:1159} INFO - Dependencies all met for dep_context=requeueable deps ti=<TaskInstance: s3_pose_v2.upload_to_s3 scheduled__2023-11-28T14:33:17.814459+00:00 [queued]>
[2023-11-29T16:11:36.325+0000] {taskinstance.py:1361} INFO - Starting attempt 2 of 2
[2023-11-29T16:11:36.576+0000] {taskinstance.py:1382} INFO - Executing <Task(PythonOperator): upload_to_s3> on 2023-11-28 14:33:17.814459+00:00
[2023-11-29T16:11:36.611+0000] {standard_task_runner.py:57} INFO - Started process 2789 to run task
[2023-11-29T16:11:36.626+0000] {standard_task_runner.py:84} INFO - Running: ['***', 'tasks', 'run', 's3_pose_v2', 'upload_to_s3', 'scheduled__2023-11-28T14:33:17.814459+00:00', '--job-id', '77', '--raw', '--subdir', 'DAGS_FOLDER/post_s3.py', '--cfg-path', '/tmp/tmp8xx8int8']
[2023-11-29T16:11:36.635+0000] {standard_task_runner.py:85} INFO - Job 77: Subtask upload_to_s3
[2023-11-29T16:11:38.362+0000] {task_command.py:416} INFO - Running <TaskInstance: s3_pose_v2.upload_to_s3 scheduled__2023-11-28T14:33:17.814459+00:00 [running]> on host a89a99bc45b2
[2023-11-29T16:11:40.592+0000] {taskinstance.py:1662} INFO - Exporting env vars: AIRFLOW_CTX_DAG_OWNER='Dashrath' AIRFLOW_CTX_DAG_ID='s3_pose_v2' AIRFLOW_CTX_TASK_ID='upload_to_s3' AIRFLOW_CTX_EXECUTION_DATE='2023-11-28T14:33:17.814459+00:00' AIRFLOW_CTX_TRY_NUMBER='2' AIRFLOW_CTX_DAG_RUN_ID='scheduled__2023-11-28T14:33:17.814459+00:00'
[2023-11-29T16:11:41.034+0000] {base.py:73} INFO - Using connection ID 'aws_conn' for task execution.
[2023-11-29T16:11:41.042+0000] {connection_wrapper.py:378} INFO - AWS Connection (conn_id='aws_conn', conn_type='aws') credentials retrieved from login and password.
[2023-11-29T16:11:45.680+0000] {taskinstance.py:1937} ERROR - Task failed with exception
Traceback (most recent call last):
  File "/home/airflow/.local/lib/python3.8/site-packages/airflow/operators/python.py", line 192, in execute
    return_value = self.execute_callable()
  File "/home/airflow/.local/lib/python3.8/site-packages/airflow/operators/python.py", line 209, in execute_callable
    return self.python_callable(*self.op_args, **self.op_kwargs)
  File "/opt/airflow/dags/post_s3.py", line 32, in upload_to_s3
    s3_hook.load_file(
  File "/home/airflow/.local/lib/python3.8/site-packages/airflow/providers/amazon/aws/hooks/s3.py", line 135, in wrapper
    return func(*bound_args.args, **bound_args.kwargs)
  File "/home/airflow/.local/lib/python3.8/site-packages/airflow/providers/amazon/aws/hooks/s3.py", line 89, in wrapper
    return func(*bound_args.args, **bound_args.kwargs)
  File "/home/airflow/.local/lib/python3.8/site-packages/airflow/providers/amazon/aws/hooks/s3.py", line 1082, in load_file
    client.upload_file(filename, bucket_name, key, ExtraArgs=extra_args, Config=self.transfer_config)
  File "/home/airflow/.local/lib/python3.8/site-packages/boto3/s3/inject.py", line 143, in upload_file
    return transfer.upload_file(
  File "/home/airflow/.local/lib/python3.8/site-packages/boto3/s3/transfer.py", line 292, in upload_file
    future.result()
  File "/home/airflow/.local/lib/python3.8/site-packages/s3transfer/futures.py", line 103, in result
    return self._coordinator.result()
  File "/home/airflow/.local/lib/python3.8/site-packages/s3transfer/futures.py", line 266, in result
    raise self._exception
  File "/home/airflow/.local/lib/python3.8/site-packages/s3transfer/tasks.py", line 269, in _main
    self._submit(transfer_future=transfer_future, **kwargs)
  File "/home/airflow/.local/lib/python3.8/site-packages/s3transfer/upload.py", line 591, in _submit
    upload_input_manager.provide_transfer_size(transfer_future)
  File "/home/airflow/.local/lib/python3.8/site-packages/s3transfer/upload.py", line 244, in provide_transfer_size
    self._osutil.get_file_size(transfer_future.meta.call_args.fileobj)
  File "/home/airflow/.local/lib/python3.8/site-packages/s3transfer/utils.py", line 247, in get_file_size
    return os.path.getsize(filename)
  File "/usr/local/lib/python3.8/genericpath.py", line 50, in getsize
    return os.stat(filename).st_size
FileNotFoundError: [Errno 2] No such file or directory: '/home/dashrath/Desktop/doc-air/dags/post_data.txt'
[2023-11-29T16:11:45.884+0000] {taskinstance.py:1400} INFO - Marking task as FAILED. dag_id=s3_pose_v2, task_id=upload_to_s3, execution_date=20231128T143317, start_date=20231129T161136, end_date=20231129T161145
[2023-11-29T16:11:46.385+0000] {standard_task_runner.py:104} ERROR - Failed to execute job 77 for task upload_to_s3 ([Errno 2] No such file or directory: '/home/dashrath/Desktop/doc-air/dags/post_data.txt'; 2789)
[2023-11-29T16:11:46.694+0000] {local_task_job_runner.py:228} INFO - Task exited with return code 1
[2023-11-29T16:11:47.790+0000] {taskinstance.py:2778} INFO - 0 downstream tasks scheduled from follow-on schedule check
