[2023-11-29T13:25:01.995+0000] {taskinstance.py:1159} INFO - Dependencies all met for dep_context=non-requeueable deps ti=<TaskInstance: rest_api.upload_s3 manual__2023-11-29T13:24:28.196356+00:00 [queued]>
[2023-11-29T13:25:02.030+0000] {taskinstance.py:1159} INFO - Dependencies all met for dep_context=requeueable deps ti=<TaskInstance: rest_api.upload_s3 manual__2023-11-29T13:24:28.196356+00:00 [queued]>
[2023-11-29T13:25:02.030+0000] {taskinstance.py:1361} INFO - Starting attempt 1 of 2
[2023-11-29T13:25:02.164+0000] {taskinstance.py:1382} INFO - Executing <Task(PythonOperator): upload_s3> on 2023-11-29 13:24:28.196356+00:00
[2023-11-29T13:25:02.234+0000] {standard_task_runner.py:57} INFO - Started process 1895 to run task
[2023-11-29T13:25:02.237+0000] {standard_task_runner.py:84} INFO - Running: ['***', 'tasks', 'run', 'rest_api', 'upload_s3', 'manual__2023-11-29T13:24:28.196356+00:00', '--job-id', '65', '--raw', '--subdir', 'DAGS_FOLDER/rest_api.py', '--cfg-path', '/tmp/tmpag3_duqq']
[2023-11-29T13:25:02.289+0000] {standard_task_runner.py:85} INFO - Job 65: Subtask upload_s3
[2023-11-29T13:25:03.248+0000] {task_command.py:416} INFO - Running <TaskInstance: rest_api.upload_s3 manual__2023-11-29T13:24:28.196356+00:00 [running]> on host a89a99bc45b2
[2023-11-29T13:25:04.748+0000] {taskinstance.py:1662} INFO - Exporting env vars: AIRFLOW_CTX_DAG_OWNER='Dashrath' AIRFLOW_CTX_DAG_ID='rest_api' AIRFLOW_CTX_TASK_ID='upload_s3' AIRFLOW_CTX_EXECUTION_DATE='2023-11-29T13:24:28.196356+00:00' AIRFLOW_CTX_TRY_NUMBER='1' AIRFLOW_CTX_DAG_RUN_ID='manual__2023-11-29T13:24:28.196356+00:00'
[2023-11-29T13:25:04.827+0000] {base.py:73} INFO - Using connection ID 'aws_conn' for task execution.
[2023-11-29T13:25:04.839+0000] {connection_wrapper.py:378} INFO - AWS Connection (conn_id='aws_conn', conn_type='aws') credentials retrieved from login and password.
[2023-11-29T13:25:26.014+0000] {taskinstance.py:1937} ERROR - Task failed with exception
Traceback (most recent call last):
  File "/home/airflow/.local/lib/python3.8/site-packages/airflow/operators/python.py", line 192, in execute
    return_value = self.execute_callable()
  File "/home/airflow/.local/lib/python3.8/site-packages/airflow/operators/python.py", line 209, in execute_callable
    return self.python_callable(*self.op_args, **self.op_kwargs)
  File "/opt/airflow/dags/rest_api.py", line 17, in upload
    hook.load_file(filename=filename, key = key, bucket_name=bucket_name)
  File "/home/airflow/.local/lib/python3.8/site-packages/airflow/providers/amazon/aws/hooks/s3.py", line 135, in wrapper
    return func(*bound_args.args, **bound_args.kwargs)
  File "/home/airflow/.local/lib/python3.8/site-packages/airflow/providers/amazon/aws/hooks/s3.py", line 89, in wrapper
    return func(*bound_args.args, **bound_args.kwargs)
  File "/home/airflow/.local/lib/python3.8/site-packages/airflow/providers/amazon/aws/hooks/s3.py", line 1082, in load_file
    client.upload_file(filename, bucket_name, key, ExtraArgs=extra_args, Config=self.transfer_config)
  File "/home/airflow/.local/lib/python3.8/site-packages/boto3/s3/inject.py", line 143, in upload_file
    return transfer.upload_file(
  File "/home/airflow/.local/lib/python3.8/site-packages/boto3/s3/transfer.py", line 292, in upload_file
    future.result()
  File "/home/airflow/.local/lib/python3.8/site-packages/s3transfer/futures.py", line 103, in result
    return self._coordinator.result()
  File "/home/airflow/.local/lib/python3.8/site-packages/s3transfer/futures.py", line 266, in result
    raise self._exception
  File "/home/airflow/.local/lib/python3.8/site-packages/s3transfer/tasks.py", line 269, in _main
    self._submit(transfer_future=transfer_future, **kwargs)
  File "/home/airflow/.local/lib/python3.8/site-packages/s3transfer/upload.py", line 591, in _submit
    upload_input_manager.provide_transfer_size(transfer_future)
  File "/home/airflow/.local/lib/python3.8/site-packages/s3transfer/upload.py", line 244, in provide_transfer_size
    self._osutil.get_file_size(transfer_future.meta.call_args.fileobj)
  File "/home/airflow/.local/lib/python3.8/site-packages/s3transfer/utils.py", line 247, in get_file_size
    return os.path.getsize(filename)
  File "/usr/local/lib/python3.8/genericpath.py", line 50, in getsize
    return os.stat(filename).st_size
FileNotFoundError: [Errno 2] No such file or directory: '/home/dashrath/Desktop/doc-air/dags/post_data.csv'
[2023-11-29T13:25:26.313+0000] {taskinstance.py:1400} INFO - Marking task as UP_FOR_RETRY. dag_id=rest_api, task_id=upload_s3, execution_date=20231129T132428, start_date=20231129T132502, end_date=20231129T132526
[2023-11-29T13:25:26.694+0000] {standard_task_runner.py:104} ERROR - Failed to execute job 65 for task upload_s3 ([Errno 2] No such file or directory: '/home/dashrath/Desktop/doc-air/dags/post_data.csv'; 1895)
[2023-11-29T13:25:26.741+0000] {local_task_job_runner.py:228} INFO - Task exited with return code 1
[2023-11-29T13:25:26.985+0000] {taskinstance.py:2778} INFO - 0 downstream tasks scheduled from follow-on schedule check
