[2023-11-30T10:16:37.043+0000] {taskinstance.py:1159} INFO - Dependencies all met for dep_context=non-requeueable deps ti=<TaskInstance: download_s3.download_csv manual__2023-11-30T10:13:35.992542+00:00 [queued]>
[2023-11-30T10:16:37.157+0000] {taskinstance.py:1159} INFO - Dependencies all met for dep_context=requeueable deps ti=<TaskInstance: download_s3.download_csv manual__2023-11-30T10:13:35.992542+00:00 [queued]>
[2023-11-30T10:16:37.158+0000] {taskinstance.py:1361} INFO - Starting attempt 1 of 2
[2023-11-30T10:16:37.406+0000] {taskinstance.py:1382} INFO - Executing <Task(PythonOperator): download_csv> on 2023-11-30 10:13:35.992542+00:00
[2023-11-30T10:16:37.420+0000] {standard_task_runner.py:57} INFO - Started process 904 to run task
[2023-11-30T10:16:37.475+0000] {standard_task_runner.py:84} INFO - Running: ['***', 'tasks', 'run', 'download_s3', 'download_csv', 'manual__2023-11-30T10:13:35.992542+00:00', '--job-id', '97', '--raw', '--subdir', 'DAGS_FOLDER/download_s3.py', '--cfg-path', '/tmp/tmp1hqyq9tr']
[2023-11-30T10:16:37.515+0000] {standard_task_runner.py:85} INFO - Job 97: Subtask download_csv
[2023-11-30T10:16:38.437+0000] {task_command.py:416} INFO - Running <TaskInstance: download_s3.download_csv manual__2023-11-30T10:13:35.992542+00:00 [running]> on host ef0d87b1d156
[2023-11-30T10:16:40.177+0000] {taskinstance.py:1662} INFO - Exporting env vars: AIRFLOW_CTX_DAG_OWNER='Dashrath' AIRFLOW_CTX_DAG_ID='download_s3' AIRFLOW_CTX_TASK_ID='download_csv' AIRFLOW_CTX_EXECUTION_DATE='2023-11-30T10:13:35.992542+00:00' AIRFLOW_CTX_TRY_NUMBER='1' AIRFLOW_CTX_DAG_RUN_ID='manual__2023-11-30T10:13:35.992542+00:00'
[2023-11-30T10:16:40.198+0000] {taskinstance.py:1937} ERROR - Task failed with exception
Traceback (most recent call last):
  File "/home/airflow/.local/lib/python3.8/site-packages/airflow/operators/python.py", line 192, in execute
    return_value = self.execute_callable()
  File "/home/airflow/.local/lib/python3.8/site-packages/airflow/operators/python.py", line 209, in execute_callable
    return self.python_callable(*self.op_args, **self.op_kwargs)
  File "/opt/airflow/dags/download_s3.py", line 23, in download
    hook.download_file(key=key, bucket_name=bucket_name, filename =filename )
  File "/home/airflow/.local/lib/python3.8/site-packages/airflow/providers/amazon/aws/hooks/s3.py", line 120, in wrapper
    bound_args = function_signature.bind(*args, **kwargs)
  File "/usr/local/lib/python3.8/inspect.py", line 3037, in bind
    return self._bind(args, kwargs)
  File "/usr/local/lib/python3.8/inspect.py", line 3026, in _bind
    raise TypeError(
TypeError: got an unexpected keyword argument 'filename'
[2023-11-30T10:16:41.097+0000] {taskinstance.py:1400} INFO - Marking task as UP_FOR_RETRY. dag_id=download_s3, task_id=download_csv, execution_date=20231130T101335, start_date=20231130T101637, end_date=20231130T101641
[2023-11-30T10:16:41.625+0000] {standard_task_runner.py:104} ERROR - Failed to execute job 97 for task download_csv (got an unexpected keyword argument 'filename'; 904)
[2023-11-30T10:16:41.713+0000] {local_task_job_runner.py:228} INFO - Task exited with return code 1
[2023-11-30T10:16:42.185+0000] {taskinstance.py:2778} INFO - 0 downstream tasks scheduled from follow-on schedule check
